HTTPSConnectionPool(host='ip.oxylabs.io', port=443): Max retries exceeded with url: / (Caused by ProxyError('Unable to connect to proxy', OSError('Tunnel connection failed: 503 Service Unavailable')))Traceback (most recent call last):
  File "C:\Users\sdij\PycharmProjects\medCrawling\venv\lib\site-packages\urllib3\connectionpool.py", line 776, in urlopen
    self._prepare_proxy(conn)
  File "C:\Users\sdij\PycharmProjects\medCrawling\venv\lib\site-packages\urllib3\connectionpool.py", line 1041, in _prepare_proxy
    conn.connect()
  File "C:\Users\sdij\PycharmProjects\medCrawling\venv\lib\site-packages\urllib3\connection.py", line 618, in connect
    self._tunnel()  # type: ignore[attr-defined]
  File "C:\Users\sdij\AppData\Local\Programs\Python\Python38\lib\http\client.py", line 898, in _tunnel
    raise OSError("Tunnel connection failed: %d %s" % (code,
OSError: Tunnel connection failed: 503 Service Unavailable

The above exception was the direct cause of the following exception:

urllib3.exceptions.ProxyError: ('Unable to connect to proxy', OSError('Tunnel connection failed: 503 Service Unavailable'))

The above exception was the direct cause of the following exception:

Traceback (most recent call last):
  File "C:\Users\sdij\PycharmProjects\medCrawling\venv\lib\site-packages\requests\adapters.py", line 486, in send
    resp = conn.urlopen(
  File "C:\Users\sdij\PycharmProjects\medCrawling\venv\lib\site-packages\urllib3\connectionpool.py", line 844, in urlopen
    retries = retries.increment(
  File "C:\Users\sdij\PycharmProjects\medCrawling\venv\lib\site-packages\urllib3\util\retry.py", line 515, in increment
    raise MaxRetryError(_pool, url, reason) from reason  # type: ignore[arg-type]
urllib3.exceptions.MaxRetryError: HTTPSConnectionPool(host='ip.oxylabs.io', port=443): Max retries exceeded with url: / (Caused by ProxyError('Unable to connect to proxy', OSError('Tunnel connection failed: 503 Service Unavailable')))

During handling of the above exception, another exception occurred:

Traceback (most recent call last):
  File "C:/Users/sdij/PycharmProjects/medCrawling/main.py", line 404, in crawling_qna
    ipaddress = requests.get(url="https://ip.oxylabs.io/", proxies=proxy_dict)
  File "C:\Users\sdij\PycharmProjects\medCrawling\venv\lib\site-packages\requests\api.py", line 73, in get
    return request("get", url, params=params, **kwargs)
  File "C:\Users\sdij\PycharmProjects\medCrawling\venv\lib\site-packages\requests\api.py", line 59, in request
    return session.request(method=method, url=url, **kwargs)
  File "C:\Users\sdij\PycharmProjects\medCrawling\venv\lib\site-packages\requests\sessions.py", line 587, in request
    resp = self.send(prep, **send_kwargs)
  File "C:\Users\sdij\PycharmProjects\medCrawling\venv\lib\site-packages\requests\sessions.py", line 701, in send
    r = adapter.send(request, **kwargs)
  File "C:\Users\sdij\PycharmProjects\medCrawling\venv\lib\site-packages\requests\adapters.py", line 513, in send
    raise ProxyError(e, request=request)
requests.exceptions.ProxyError: HTTPSConnectionPool(host='ip.oxylabs.io', port=443): Max retries exceeded with url: / (Caused by ProxyError('Unable to connect to proxy', OSError('Tunnel connection failed: 503 Service Unavailable')))
